Workbook

Sheet Summary
B2: INCOME | H2: Start Up Package | I2: 1460357
B3: Account | C3: FY24 | D3: FY25 | E3: FY26 | F3: Total | H3: Received | I3: =F10 -> 1039462.1
B4: 1101935 | C4: ='1101935 FY24'!J7 -> 500000 | D4: ='1101935 FY25'!J7 -> 219462 | E4: 0 | F4: =SUM(C4:E4) -> 719462 | H4: Remaining | I4: =I2-I3 -> 420894.93
B5: 5406011 | C5: ='5406011 FY24'!J7 -> 20000 | D5: 0 | E5: 0 | F5: =SUM(C5:E5) -> 20000
B6: 2176351 | C6: 0 | D6: 0 | E6: 0 | F6: =SUM(C6:E6) -> 0
B7: 2176300 BMEAM | C7: 0 | D7: 0 | E7: 0 | F7: =SUM(C7:E7) -> 0
B8: 2215510 BMEAM | C8: ='2215510 BME AM FY24'!J8 -> 300000.07 | D8: 0 | E8: 0 | F8: =SUM(C8:E8) -> 300000.07
B9: 2176301 BMEAM | C9: 0 | D9: 0 | E9: 0 | F9: =SUM(C9:E9) -> 0
B10: Total | C10: =SUM(C4:C9) -> 820000.07 | D10: =SUM(D4:D9) -> 219462 | E10: =SUM(E4:E9) -> 0 | F10: =SUM(F4:F9) -> 1039462.1
B13: EXPENSES
B14: Account | C14: FY24 | D14: FY25 | E14: FY26 | F14: Total
B15: 1101935 | C15: ='1101935 FY24'!H31 -> 452230.88 | D15: ='1101935 FY25'!H40 -> 153596.44 | E15: ='1101935 FY26'!G14+'1101935 FY26'!I14 -> 40507.04 | F15: =SUM(C15:E15) -> 646334.36
B16: 5406011 | C16: ='5406011 FY24'!H10 -> 20000.18 | D16: 0 | E16: 0 | F16: =SUM(C16:E16) -> 20000.18
B17: 2176351 | C17: 0 | D17: ='2176351 FY25'!H9 -> 3284.87 | E17: ='2176351 FY26'!H8 -> 330.37 | F17: =SUM(C17:E17) -> 3615.24
B18: 2176300 BMEAM | C18: ='2176300 BMEAM FY24'!H8 -> 217.6 | D18: ='2176300 BMEAM FY25'!H21 -> 24071.36 | E18: 0 | F18: =SUM(C18:E18) -> 24288.96
B19: 2215510 BMEAM | C19: ='2215510 BME AM FY24'!H11 -> 300000.07 | D19: 0 | E19: 0 | F19: =SUM(C19:E19) -> 300000.07
B20: 2176301 BMEAM | C20: 0 | D20: 0 | E20: 0 | F20: =SUM(C20:E20) -> 0
B21: Total | C21: =SUM(C15:C20) -> 772448.73 | D21: =SUM(D15:D20) -> 180952.67 | E21: =SUM(E15:E20) -> 40837.41 | F21: =SUM(F15:F20) -> 994238.81
B24: AVAILABLE BALANCE
B25: Account | C25: FY24 | D25: FY25 | E25: FY26 | F25: FY26 ACTUALS
B26: 1101935 | C26: =C4-C15 -> 47769.12 | D26: =D4-D15 -> 65865.56 | E26: =E4-E15 -> -40507.04 | F26: =SUM(C26:E26) -> 73127.64
B27: 5406011 | C27: =C5-C16 -> -0.18 | D27: =D5-D16 -> 0 | E27: =E5-E16 -> 0 | F27: =SUM(C27:E27) -> -0.18
B28: 2176351 | C28: =C6-C17 -> 0 | D28: =D6-D17 -> -3284.87 | E28: =E6-E17 -> -330.37 | F28: =SUM(C28:E28) -> -3615.24
B29: 2176300 BMEAM | C29: =C7-C18 -> -217.6 | D29: =D7-D18 -> -24071.36 | E29: =E7-E18 -> 0 | F29: =SUM(C29:E29) -> -24288.96
B30: 2215510 BMEAM | C30: =C8-C19 -> 0 | D30: =D8-D19 -> 0 | E30: =E8-E19 -> 0 | F30: =SUM(C30:E30) -> 0
B31: 2176301 BMEAM | C31: =C9-C20 -> 0 | D31: =D9-D20 -> 0 | E31: =E9-E20 -> 0 | F31: =SUM(C31:E31) -> 0
B32: Total | C32: =SUM(C26:C31) -> 47551.34 | D32: =SUM(D26:D31) -> 38509.33 | E32: =SUM(E26:E31) -> -40837.41 | F32: =SUM(F26:F31) -> 45223.26

Sheet 1101935 FY24
B2: INCOME AND EXPENSE REPORT | L2: TRANSACTION REPORT | AC2: PAYROLL REPORT
B4: Account Number | C4: Consolidation Object Name | D4: Object Code | E4: Object Code Name | F4: Current Budget | G4: Fiscal Year Actuals | H4: Inception to Date | I4: Open Encumbrances | J4: Balance Available | L4: Object Code | M4: Object Code Name | N4: Transaction Date | O4: Document | P4: Document Number | Q4: Origin | R4: e-Doc Link | S4: Post Date | T4: Reference Document Number | U4: Organization Document Number | V4: Entry | W4: Document Description | X4: Vendor Name | Y4: Current Budget Amount | Z4: Current Month Actuals | AA4: Encumbrance Amount | AC4: Account Number | AD4: Sub Account Number | AE4: Employee Name | AF4: Position Number | AG4: Object Code | AH4: Object Code Name | AI4: Pay Period Earn Date | AJ4: Document Type Code | AK4: Job FTE | AL4: Hours Worked | AM4: Expenditure Amount
B5: 1101935 | C5: OTHER REVENUE | D5: 0899 | E5: Net Revenues - FSO Only | F5: 0 | G5: 0 | H5: 0 | I5: 0 | J5: 0 | L5: 0932 | M5: Budget Adjustment Income Transfer | N5: 45448 | O5: TF | P5: B212966 | Q5: BO | R5: Link Not Available | S5: 45448 | T5: - | U5: 2024060450 | V5: FY24 BME NEI CANCER ENGR ALLOCATION_ALE | W5: - | X5: - | Y5: 0 | Z5: -500000 | AA5: 0 | AC5: 1101935 | AD5: - | AE5: McGhee,Alexander | AF5: 1867411 | AG5: 1212 | AH5: Supp Com Regular App/Fac (ere 4) | AI5: 45438 | AJ5: LLPR | AK5: 0.025 | AL5: 40 | AM5: 3216.4
C6: TRANSFER OF FUNDS | D6: 0932 | E6: Budget Adjustment Income Transfer | F6: 0 | G6: -500000 | H6: -500000 | I6: 0 | J6: 500000 | L6: 0932 Total | Y6: 0 | Z6: -500000 | AA6: 0 | AI6: 45452 | AJ6: LLPR | AK6: 0.025 | AL6: 32 | AM6: 2573.12
C7: INCOME Total | F7: 0 | G7: -500000 | H7: -500000 | I7: 0 | J7: 500000 | L7: 1000 | M7: Personal Services-Budget | N7: 45446 | O7: BTR | P7: B212966 | Q7: BO | R7: Link Not Available | S7: 45448 | T7: - | U7: 2024060450 | V7: FY24 BME NEI CANCER ENGR ALLOCATION_ALE | W7: - | X7: - | Y7: 500000 | Z7: 0 | AA7: 0 | AI7: 45466 | AJ7: LLPR | AK7: 0.025 | AL7: 72 | AM7: 5789.52
C8: PERSONAL SERVICES | D8: 1000 | E8: Personal Services-Budget | F8: 500000 | G8: 0 | H8: 0 | I8: 0 | J8: 500000 | L8: 1000 Total | Y8: 500000 | Z8: 0 | AA8: 0 | AI8: 45480 | AJ8: LLPR | AK8: 0.025 | AL8: 40 | AM8: 3216.4
D9: 1212 | E9: Supp Com Regular App/Fac (ere 4) | F9: 0 | G9: 14795.44 | H9: 14795.44 | I9: 0 | J9: -14795.44 | L9: 1212 | M9: Supp Com Regular App/Fac (ere 4) | N9: 45434 | O9: LLPE | P9: 20240522200001 | Q9: UE | R9: Link Not Available | S9: 45434 | T9: - | U9: - | V9: PAYROLL ENCUMBRANCES | W9: - | X9: - | Y9: 0 | Z9: 0 | AA9: 563 | AG9: 1212 Total | AL9: 184 | AM9: 14795.44
D10: 2121 | E10: Employee Full-Benefit ERE | F10: 0 | G10: 4734.55 | H10: 4734.55 | I10: 0 | J10: -4734.55 | N10: 45441 | O10: LLPE | P10: 20240529200001 | Q10: MF | R10: Link Not Available | S10: 45441 | T10: - | U10: - | V10: PAYROLL ENCUMBRANCES | W10: - | X10: - | Y10: 0 | Z10: 0 | AA10: -161 | AG10: 2121 | AH10: Employee Full-Benefit ERE | AI10: 45438 | AJ10: LLPR | AK10: 0.025 | AL10: 0 | AM10: 1029.25
C11: GENERAL EXPENSES | D11: 3590 | E11: R/M Services-Office Furniture & Equipment | F11: 0 | G11: 196.08 | H11: 196.08 | I11: 0 | J11: -196.08 | O11: LLPR | P11: 20240531100001 | Q11: UE | R11: Link Not Available | S11: 45441 | T11: - | U11: 11 | V11: NORMAL PAYROLL ACTIVITY | W11: - | X11: - | Y11: 0 | Z11: 3216.4 | AA11: 0 | AI11: 45452 | AJ11: LLPR | AK11: 0.025 | AL11: 0 | AM11: 823.4
D12: 3780 | E12: R/M Services-Other | F12: 0 | G12: 81.56 | H12: 81.56 | I12: 0 | J12: -81.56 | N12: 45455 | O12: LLPE | P12: 20240612200001 | Q12: MF | R12: Link Not Available | S12: 45455 | T12: - | U12: - | V12: PAYROLL ENCUMBRANCES | W12: - | X12: - | Y12: 0 | Z12: 0 | AA12: -161 | AI12: 45466 | AJ12: LLPR | AK12: 0.025 | AL12: 0 | AM12: 1852.65
D13: 3880 | E13: Shipping & Handling | F13: 0 | G13: 40 | H13: 40 | I13: 0 | J13: -40 | N13: 45469 | O13: LLPE | P13: 20240626200001 | Q13: MF | R13: Link Not Available | S13: 45469 | T13: - | U13: - | V13: PAYROLL ENCUMBRANCES | W13: - | X13: - | Y13: 0 | Z13: 0 | AA13: -161 | AI13: 45480 | AJ13: LLPR | AK13: 0.025 | AL13: 0 | AM13: 1029.25
D14: 5230 | E14: Office Supplies | F14: 0 | G14: 1143.34 | H14: 1143.34 | I14: 0 | J14: -1143.34 | O14: LLPR | P14: 20240628100001 | Q14: UE | R14: Link Not Available | S14: 45469 | T14: - | U14: 12 | V14: NORMAL PAYROLL ACTIVITY | W14: - | X14: - | Y14: 0 | Z14: 8362.64 | AA14: 0 | AG14: 2121 Total | AL14: 0 | AM14: 4734.55
D15: 5260 | E15: R/M Supplies - Shop | F15: 0 | G15: 441.8 | H15: 441.8 | I15: 0 | J15: -441.8 | N15: 45483 | O15: LLPR | P15: 20240712100001 | Q15: UE | R15: Link Not Available | S15: 45483 | T15: - | U15: 12 | V15: NORMAL PAYROLL ACTIVITY | W15: - | X15: - | Y15: 0 | Z15: 3216.4 | AA15: 0 | AD15: - Total | AL15: 184 | AM15: 19529.99
D16: 5270 | E16: R/M Supplies - Other | F16: 0 | G16: 1757.21 | H16: 1757.21 | I16: 0 | J16: -1757.21 | N16: 45485 | O16: LLPE | P16: 20240630200000 | Q16: MF | R16: Link Not Available | S16: 45485 | T16: - | U16: - | V16: PAYROLL ENCUMBRANCES | W16: - | X16: - | Y16: 0 | Z16: 0 | AA16: -80 | AC16: 1101935 Total | AL16: 184 | AM16: 19529.99
D17: 5290 | E17: Research Supplies/Medical - Laboratory | F17: 0 | G17: 11720.26 | H17: 11720.26 | I17: 0 | J17: -11720.26 | L17: 1212 Total | Y17: 0 | Z17: 14795.44 | AA17: 0 | AC17: Grand Total | AL17: 184 | AM17: 19529.99
D18: 5490 | E18: Operating Supplies - Other | F18: 0 | G18: 11705.31 | H18: 11705.31 | I18: 0 | J18: -11705.31 | L18: 2121 | M18: Employee Full-Benefit ERE | N18: 45434 | O18: LLPE | P18: 20240522200001 | Q18: UE | R18: Link Not Available | S18: 45434 | T18: - | U18: - | V18: PAYROLL ENCUMBRANCES | W18: - | X18: - | Y18: 0 | Z18: 0 | AA18: 180.16
D19: 5520 | E19: Conference Registration Fees | F19: 0 | G19: 1400 | H19: 1400 | I19: 0 | J19: -1400 | N19: 45441 | O19: LLPE | P19: 20240529200001 | Q19: MF | R19: Link Not Available | S19: 45441 | T19: - | U19: - | V19: PAYROLL ENCUMBRANCES | W19: - | X19: - | Y19: 0 | Z19: 0 | AA19: -51.52
D20: 5535 | E20: Purchasing Transaction Fees | F20: 0 | G20: 54.75 | H20: 54.75 | I20: 0 | J20: -54.75 | O20: LLPR | P20: 20240531100001 | Q20: UE | R20: Link Not Available | S20: 45441 | T20: - | U20: 11 | V20: NORMAL PAYROLL ACTIVITY | W20: - | X20: - | Y20: 0 | Z20: 1029.25 | AA20: 0
D21: 5560 | E21: Freight In/Out - (Noncapital related) | F21: 0 | G21: 1046.41 | H21: 1046.41 | I21: 0 | J21: -1046.41 | N21: 45455 | O21: LLPE | P21: 20240612200001 | Q21: MF | R21: Link Not Available | S21: 45455 | T21: - | U21: - | V21: PAYROLL ENCUMBRANCES | W21: - | X21: - | Y21: 0 | Z21: 0 | AA21: -51.52
D22: 5760 | E22: Noncapitalized Equipment - EDP | F22: 0 | G22: 5550.42 | H22: 5550.42 | I22: 0 | J22: -5550.42 | N22: 45469 | O22: LLPE | P22: 20240626200001 | Q22: MF | R22: Link Not Available | S22: 45469 | T22: - | U22: - | V22: PAYROLL ENCUMBRANCES | W22: - | X22: - | Y22: 0 | Z22: 0 | AA22: -51.52
D23: 5770 | E23: Noncapitalized Equipment - Other | F23: 0 | G23: 49076.25 | H23: 49076.25 | I23: 483.2 | J23: -49559.45 | O23: LLPR | P23: 20240628100001 | Q23: UE | R23: Link Not Available | S23: 45469 | T23: - | U23: 12 | V23: NORMAL PAYROLL ACTIVITY | W23: - | X23: - | Y23: 0 | Z23: 2676.05 | AA23: 0
D24: 5775 | E24: Noncapitalized Furnishings | F24: 0 | G24: 2457.94 | H24: 2457.94 | I24: 0 | J24: -2457.94 | N24: 45483 | O24: LLPR | P24: 20240712100001 | Q24: UE | R24: Link Not Available | S24: 45483 | T24: - | U24: 12 | V24: NORMAL PAYROLL ACTIVITY | W24: - | X24: - | Y24: 0 | Z24: 1029.25 | AA24: 0
D25: 5780 | E25: Miscellaneous - Other Operating | F25: 0 | G25: 788.57 | H25: 788.57 | I25: 0 | J25: -788.57 | N25: 45485 | O25: LLPE | P25: 20240630200000 | Q25: MF | R25: Link Not Available | S25: 45485 | T25: - | U25: - | V25: PAYROLL ENCUMBRANCES | W25: - | X25: - | Y25: 0 | Z25: 0 | AA25: -25.6
D26: 5899 | E26: Net Expenses - FSO Only | F26: 0 | G26: 0 | H26: 0 | I26: 0 | J26: 0 | L26: 2121 Total | Y26: 0 | Z26: 4734.55 | AA26: -2.8421709e-14
C27: TRAVEL | D27: 6240 | E27: TRAVEL-OUT STATE | F27: 0 | G27: 142.27 | H27: 142.27 | I27: 0 | J27: -142.27 | L27: 3590 | M27: R/M Services-Office Furniture & Equipmen | N27: 45365 | O27: PCDO | P27: 27221074 | Q27: 01 | R27: View Document | S27: 45365 | T27: - | U27: - | V27: Paint, Pure Tung Oil, Orange Peel Oil | W27: Procurement Card - 5745 / MCGHEE, ALEXANDER / 3737 / AMZN Mktp US RN6LU60V2 / $196.08 | X27: - | Y27: 0 | Z27: 196.08 | AA27: 0
D28: 6241 | E28: TRAVEL-OUT OF STATE AIRLINES | F28: 0 | G28: 1399.15 | H28: 1399.15 | I28: 0 | J28: -1399.15 | L28: 3590 Total | Y28: 0 | Z28: 196.08 | AA28: 0
D29: 6242 | E29: TRAVEL-OUT STATE HOTEL | F29: 0 | G29: 847.86 | H29: 847.86 | I29: 0 | J29: -847.86 | L29: 3780 | M29: R/M Services-Other | N29: 45462 | O29: PCDO | P29: 28040101 | Q29: 01 | R29: View Document | S29: 45463 | T29: - | U29: - | V29: Supplies | W29: Procurement Card - 5745 / MCGHEE, ALEXANDER / 44619 / THE HOME DEPOT #0486 / $81.56 | X29: - | Y29: 0 | Z29: 81.56 | AA29: 0
C30: CAPITAL | D30: 7690 | E30: Scientific Equipment | F30: 0 | G30: 342851.71 | H30: 342851.71 | I30: 13409.23 | J30: -356260.94 | L30: 3780 Total | Y30: 0 | Z30: 81.56 | AA30: 0
C31: EXPENSES Total | F31: 500000 | G31: 452230.88 | H31: 452230.88 | I31: 13892.43 | J31: 33876.69 | L31: 3880 | M31: Shipping & Handling | N31: 45342 | O31: PCDO | P31: 26987701 | Q31: 01 | R31: View Document | S31: 45342 | T31: - | U31: - | V31: Office and lab Reno Supplies SandH | W31: Procurement Card - 3322 / CANCER CENTER, ARIZONA / 4382589607001 / AMZN MKTP US / $577.92 | X31: - | Y31: 0 | Z31: 40 | AA31: 0
B32: Grand Total | F32: 500000 | G32: -47769.12 | H32: -47769.12 | I32: 13892.43 | J32: 533876.69 | L32: 3880 Total | Y32: 0 | Z32: 40 | AA32: 0
L33: 5230 | M33: Office Supplies | N33: 45412 | O33: PCDO | P33: 27640100 | Q33: 01 | R33: View Document | S33: 45412 | T33: - | U33: - | V33: office supplies- storage bins | W33: Procurement Card - 5745 / MCGHEE, ALEXANDER / 23105 / AMZN Mktp US QK45I4KX3 / $1065.10 | X33: - | Y33: 0 | Z33: 1065.1 | AA33: 0
N34: 45414 | O34: PCDO | P34: 27596330 | Q34: 01 | R34: View Document | S34: 45414 | T34: - | U34: - | V34: office supplies- storage boxes | W34: Procurement Card - 5745 / MCGHEE, ALEXANDER / 20135 / Amazon.com AG4TX44I3 / $78.24 | X34: - | Y34: 0 | Z34: 78.24 | AA34: 0
L35: 5230 Total | Y35: 0 | Z35: 1143.34 | AA35: 0
L36: 5260 | M36: R/M Supplies - Shop | N36: 45365 | O36: PCDO | P36: 27155406 | Q36: 01 | R36: View Document | S36: 45365 | T36: - | U36: - | V36: Amazon total | W36: Procurement Card - 5745 / MCGHEE, ALEXANDER / 2567 / AMZN Mktp US RW1NM8SU1 / $441.80 | X36: - | Y36: 0 | Z36: 441.8 | AA36: 0
L37: 5260 Total | Y37: 0 | Z37: 441.8 | AA37: 0
L38: 5270 | M38: R/M Supplies - Other | N38: 45365 | O38: PCDO | P38: 27249962 | Q38: 01 | R38: View Document | S38: 45365 | T38: - | U38: - | V38: Supplies for renovation | W38: Procurement Card - 5745 / MCGHEE, ALEXANDER / 4608 / THE HOME DEPOT #0414 / $294.09 | X38: - | Y38: 0 | Z38: 294.09 | AA38: 0
P39: 27249963 | Q39: 01 | R39: View Document | S39: 45365 | T39: - | U39: - | V39: Supplies for renovation | W39: Procurement Card - 5745 / MCGHEE, ALEXANDER / 4552 / AMZN Mktp US RN2AB1I82 / $522.01 | X39: - | Y39: 0 | Z39: 522.01 | AA39: 0
N40: 45373 | O40: PCDO | P40: 27287014 | Q40: 01 | R40: View Document | S40: 45373 | T40: - | U40: - | V40: 5745 / MCGHEE, ALEXANDER | W40: Procurement Card - 5745 / MCGHEE, ALEXANDER / 5650 / AMZN Mktp US / $-55.01 | X40: - | Y40: 0 | Z40: -55.01 | AA40: 0
N41: 45390 | O41: PCDO | P41: 27380726 | Q41: 01 | R41: View Document | S41: 45390 | T41: - | U41: - | V41: Supplies for lab remodel | W41: Procurement Card - 5745 / MCGHEE, ALEXANDER / 8974 / THE HOME DEPOT #0414 / $702.37 | X41: - | Y41: 0 | Z41: 702.37 | AA41: 0
P42: 27391196 | Q42: 01 | R42: View Document | S42: 45390 | T42: - | U42: - | V42: Supplies for lab remodel | W42: Procurement Card - 5745 / MCGHEE, ALEXANDER / 9730 / THE HOME DEPOT #0486 / $217.77 | X42: - | Y42: 0 | Z42: 217.77 | AA42: 0
...

Sheet 1101935 FY25
B2: INCOME AND EXPENSE REPORT | L2: TRANSACTION REPORT | AC2: PAYROLL REPORT
B4: Account Number | C4: Consolidation Object Name | D4: Object Code | E4: Object Code Name | F4: Current Budget | G4: Fiscal Year Actuals | H4: Inception to Date | I4: Open Encumbrances | J4: Balance Available | L4: Object Code | M4: Object Code Name | N4: Transaction Date | O4: Document | P4: Document Number | Q4: Origin | R4: e-Doc Link | S4: Post Date | T4: Reference Document Number | U4: Organization Document Number | V4: Entry | W4: Document Description | X4: Vendor Name | Y4: Current Budget Amount | Z4: Current Month Actuals | AA4: Encumbrance Amount | AC4: Account Number | AD4: Sub Account Number | AE4: Employee Name | AF4: Position Number | AG4: Object Code | AH4: Object Code Name | AI4: Pay Period Earn Date | AJ4: Document Type Code | AK4: Job FTE | AL4: Hours Worked | AM4: Expenditure Amount
B5: 1101935 | C5: OTHER REVENUE | D5: 0899 | E5: Net Revenues - FSO Only | F5: 0 | G5: 0 | H5: 0 | I5: 0 | J5: 0 | L5: 0932 | M5: Budget Adjustment Income Transfer | N5: 45695 | O5: TF | P5: B217367 | Q5: BO | R5: Link Not Available | S5: 45695 | T5: - | U5: 2025020750 | V5: FY25 ENGR COMMITMENT TO MCGHEE STARTUP P | W5: - | X5: - | Y5: 0 | Z5: -219462 | AA5: 0 | AC5: 1101935 | AD5: - | AE5: Declercq,Gabriel Leonard Galahad | AF5: 2004160 | AG5: 1340 | AH5: Student Wages (ere1) | AI5: 45536 | AJ5: LLPR | AK5: 0.625 | AL5: 48 | AM5: 696
C6: TRANSFER OF FUNDS | D6: 0932 | E6: Budget Adjustment Income Transfer | F6: 0 | G6: -219462 | H6: -219462 | I6: 0 | J6: 219462 | L6: 0932 Total | Y6: 0 | Z6: -219462 | AA6: 0 | AI6: 45550 | AJ6: LLPR | AK6: 0.625 | AL6: 72 | AM6: 1044
C7: INCOME Total | F7: 0 | G7: -219462 | H7: -219462 | I7: 0 | J7: 219462 | L7: 1000 | M7: Personal Services-Budget | N7: 45695 | O7: BTR | P7: B217367 | Q7: BO | R7: Link Not Available | S7: 45695 | T7: - | U7: 2025020750 | V7: FY25 ENGR COMMITMENT TO MCGHEE STARTUP P | W7: - | X7: - | Y7: 219462 | Z7: 0 | AA7: 0 | AI7: 45564 | AJ7: LLPR | AK7: 0.625 | AL7: 35 | AM7: 507.5
C8: PERSONAL SERVICES | D8: 1000 | E8: Personal Services-Budget | F8: 219462 | G8: 0 | H8: 0 | I8: 0 | J8: 219462 | L8: 1000 Total | Y8: 219462 | Z8: 0 | AA8: 0 | AI8: 45578 | AJ8: LLPR | AK8: 0.625 | AL8: 37 | AM8: 536.5
D9: 1190 | E9: Graduate Asst/Assoc Salaries (ere 8) | F9: 0 | G9: 0 | H9: 0 | I9: 0 | J9: 0 | L9: 1190 | M9: Graduate Asst/Assoc Salaries (ere 8) | N9: 45679 | O9: LLPE | P9: 20250122200001 | Q9: UE | R9: Link Not Available | S9: 45679 | T9: - | U9: - | V9: PAYROLL ENCUMBRANCES | W9: - | X9: - | Y9: 0 | Z9: 0 | AA9: 10537 | AI9: 45592 | AJ9: LLPR | AK9: 0.625 | AL9: 36.5 | AM9: 529.25
D10: 1212 | E10: Supp Com Regular App/Fac (ere 4) | F10: 0 | G10: 23479.72 | H10: 23479.72 | I10: 0 | J10: -23479.72 | N10: 45693 | O10: LLPE | P10: 20250205200001 | Q10: MF | R10: Link Not Available | S10: 45693 | T10: - | U10: - | V10: PAYROLL ENCUMBRANCES | W10: - | X10: - | Y10: 0 | Z10: 0 | AA10: -1171 | AI10: 45606 | AJ10: LLPR | AK10: 0.625 | AL10: 37 | AM10: 536.5
D11: 1213 | E11: Supp Comp Grad (ere 8) | F11: 0 | G11: 3098.54 | H11: 3098.54 | I11: 0 | J11: -3098.54 | O11: LLPR | P11: 20250207100001 | Q11: UE | R11: Link Not Available | S11: 45693 | T11: - | U11: 07 | V11: NORMAL PAYROLL ACTIVITY | W11: - | X11: - | Y11: 0 | Z11: 2341.5 | AA11: 0 | AI11: 45620 | AJ11: LLPR | AK11: 0.625 | AL11: 11.5 | AM11: 166.75
D12: 1340 | E12: Student Wages (ere1) | F12: 0 | G12: 10801.1 | H12: 10801.1 | I12: 0 | J12: -10801.1 | N12: 45695 | O12: ST | P12: 30115321 | Q12: 01 | R12: View Document | S12: 45695 | T12: - | U12: - | V12: Alia Rose Starman | W12: Salary Expense Transfer - Salary Expense Transfer Alia Starman | X12: - | Y12: 0 | Z12: -2341.5 | AA12: 0 | AI12: 45634 | AJ12: LLPR | AK12: 0.625 | AL12: 39.5 | AM12: 572.75
D13: 2117 | E13: Student Employees ERE | F13: 0 | G13: 216.04 | H13: 216.04 | I13: 0 | J13: -216.04 | N13: 45698 | O13: LLPE | P13: 20250210200000 | Q13: MF | R13: Link Not Available | S13: 45698 | T13: - | U13: - | V13: PAYROLL ENCUMBRANCES | W13: - | X13: - | Y13: 0 | Z13: 0 | AA13: -9366 | AI13: 45648 | AJ13: LLPR | AK13: 0.625 | AL13: 68 | AM13: 986
D14: 2119 | E14: Graduate Assistants ERE | F14: 0 | G14: 402.8 | H14: 402.8 | I14: 0 | J14: -402.8 | L14: 1190 Total | Y14: 0 | Z14: 0 | AA14: 0 | AI14: 45662 | AJ14: LLPR | AK14: 0.625 | AL14: 33 | AM14: 485.1
D15: 2121 | E15: Employee Full-Benefit ERE | F15: 0 | G15: 7513.52 | H15: 7513.52 | I15: 0 | J15: -7513.52 | L15: 1212 | M15: Supp Com Regular App/Fac (ere 4) | N15: 45481 | O15: LLPE | P15: 20240707200001 | Q15: UE | R15: Link Not Available | S15: 45481 | T15: - | U15: - | V15: PAYROLL ENCUMBRANCES | W15: - | X15: - | Y15: 0 | Z15: 0 | AA15: 563 | AI15: 45676 | AJ15: LLPR | AK15: 0.625 | AL15: 13 | AM15: 191.1
C16: GENERAL EXPENSES | D16: 3510 | E16: R/M Services-Buildings | F16: 0 | G16: 341.88 | H16: 341.88 | I16: 0 | J16: -341.88 | N16: 45490 | O16: LLPE | P16: 20240717200001 | Q16: MF | R16: Link Not Available | S16: 45490 | T16: - | U16: - | V16: PAYROLL ENCUMBRANCES | W16: - | X16: - | Y16: 0 | Z16: 0 | AA16: -81 | AI16: 45690 | AJ16: LLPR | AK16: 0.625 | AL16: 32 | AM16: 470.4
D17: 3870 | E17: Express Shipping | F17: 0 | G17: 95.32 | H17: 95.32 | I17: 0 | J17: -95.32 | N17: 45497 | O17: LLPE | P17: 20240724200001 | Q17: MF | R17: Link Not Available | S17: 45497 | T17: - | U17: - | V17: PAYROLL ENCUMBRANCES | W17: - | X17: - | Y17: 0 | Z17: 0 | AA17: -160 | AI17: 45704 | AJ17: LLPR | AK17: 0.625 | AL17: 55 | AM17: 808.5
D18: 4620 | E18: Software Licenses/Royalties | F18: 0 | G18: 962.34 | H18: 962.34 | I18: 0 | J18: -962.34 | O18: LLPR | P18: 20240726100001 | Q18: UE | R18: Link Not Available | S18: 45497 | T18: - | U18: 01 | V18: NORMAL PAYROLL ACTIVITY | W18: - | X18: - | Y18: 0 | Z18: 3216.4 | AA18: 0 | AI18: 45718 | AJ18: LLPR | AK18: 0.625 | AL18: 43.5 | AM18: 639.45
D19: 4840 | E19: Printing & Lithography | F19: 0 | G19: 128.91 | H19: 128.91 | I19: 0 | J19: -128.91 | N19: 45511 | O19: LLPE | P19: 20240807200001 | Q19: MF | R19: Link Not Available | S19: 45511 | T19: - | U19: - | V19: PAYROLL ENCUMBRANCES | W19: - | X19: - | Y19: 0 | Z19: 0 | AA19: -161 | AI19: 45732 | AJ19: LLPR | AK19: 0.625 | AL19: 42.5 | AM19: 624.75
D20: 5150 | E20: Data Processing Supplies | F20: 0 | G20: 102.69 | H20: 102.69 | I20: 0 | J20: -102.69 | O20: LLPR | P20: 20240809100001 | Q20: UE | R20: Link Not Available | S20: 45511 | T20: - | U20: 01 | V20: NORMAL PAYROLL ACTIVITY | W20: - | X20: - | Y20: 0 | Z20: 3216.4 | AA20: 0 | AI20: 45746 | AJ20: LLPR | AK20: 0.625 | AL20: 54 | AM20: 793.8
D21: 5180 | E21: Educational Supplies | F21: 0 | G21: 308.2 | H21: 308.2 | I21: 0 | J21: -308.2 | N21: 45525 | O21: LLPE | P21: 20240821200000 | Q21: MF | R21: Link Not Available | S21: 45525 | T21: - | U21: - | V21: PAYROLL ENCUMBRANCES | W21: - | X21: - | Y21: 0 | Z21: 0 | AA21: -161 | AI21: 45760 | AJ21: LLPR | AK21: 0.625 | AL21: 39 | AM21: 573.3
D22: 5220 | E22: Housekeeping Supplies | F22: 0 | G22: 107.62 | H22: 107.62 | I22: 0 | J22: -107.62 | O22: LLPR | P22: 20240823100001 | Q22: UE | R22: Link Not Available | S22: 45525 | T22: - | U22: 02 | V22: NORMAL PAYROLL ACTIVITY | W22: - | X22: - | Y22: 0 | Z22: 3216.4 | AA22: 0 | AI22: 45774 | AJ22: LLPR | AK22: 0.625 | AL22: 23 | AM22: 338.1
D23: 5230 | E23: Office Supplies | F23: 0 | G23: 2433.98 | H23: 2433.98 | I23: 0 | J23: -2433.98 | N23: 45796 | O23: LLPE | P23: 20250519200001 | Q23: UE | R23: Link Not Available | S23: 45796 | T23: - | U23: - | V23: PAYROLL ENCUMBRANCES | W23: - | X23: - | Y23: 0 | Z23: 0 | AA23: 418 | AI23: 45788 | AJ23: LLPR | AK23: 0.625 | AL23: 20.5 | AM23: 301.35
D24: 5260 | E24: R/M Supplies - Shop | F24: 0 | G24: 170.25 | H24: 170.25 | I24: 0 | J24: -170.25 | N24: 45819 | O24: LLPE | P24: 20250611200001 | Q24: MF | R24: Link Not Available | S24: 45819 | T24: - | U24: - | V24: PAYROLL ENCUMBRANCES | W24: - | X24: - | Y24: 0 | Z24: 0 | AA24: -161 | AG24: 1340 Total | AL24: 740 | AM24: 10801.1
D25: 5290 | E25: Research Supplies/Medical - Laboratory | F25: 0 | G25: 73587.02 | H25: 73587.02 | I25: 280.92 | J25: -73867.94 | O25: LLPR | P25: 20250613100001 | Q25: UE | R25: Link Not Available | S25: 45819 | T25: - | U25: 11 | V25: NORMAL PAYROLL ACTIVITY | W25: - | X25: - | Y25: 0 | Z25: 2573.12 | AA25: 0 | AG25: 2117 | AH25: Student Employees ERE | AI25: 45536 | AJ25: LLPR | AK25: 0.625 | AL25: 0 | AM25: 13.92
D26: 5490 | E26: Operating Supplies - Other | F26: 0 | G26: 4098.69 | H26: 4098.69 | I26: 0 | J26: -4098.69 | U26: 12 | V26: NORMAL PAYROLL ACTIVITY | W26: - | X26: - | Y26: 0 | Z26: 3216.4 | AA26: 0 | AI26: 45550 | AJ26: LLPR | AK26: 0.625 | AL26: 0 | AM26: 20.88
D27: 5520 | E27: Conference Registration Fees | F27: 0 | G27: 1044 | H27: 1044 | I27: 0 | J27: -1044 | N27: 45833 | O27: LLPE | P27: 20250625200001 | Q27: MF | R27: Link Not Available | S27: 45833 | T27: - | U27: - | V27: PAYROLL ENCUMBRANCES | W27: - | X27: - | Y27: 0 | Z27: 0 | AA27: -161 | AI27: 45564 | AJ27: LLPR | AK27: 0.625 | AL27: 0 | AM27: 10.15
D28: 5535 | E28: Purchasing Transaction Fees | F28: 0 | G28: 76.99 | H28: 76.99 | I28: 0 | J28: -76.99 | O28: LLPR | P28: 20250627100001 | Q28: UE | R28: Link Not Available | S28: 45833 | T28: - | U28: 12 | V28: NORMAL PAYROLL ACTIVITY | W28: - | X28: - | Y28: 0 | Z28: 5789.52 | AA28: 0 | AI28: 45578 | AJ28: LLPR | AK28: 0.625 | AL28: 0 | AM28: 10.73
D29: 5540 | E29: Dues | F29: 0 | G29: 265 | H29: 265 | I29: 0 | J29: -265 | N29: 45847 | O29: LLPR | P29: 20250711100001 | Q29: UE | R29: Link Not Available | S29: 45847 | T29: - | U29: 12 | V29: NORMAL PAYROLL ACTIVITY | W29: - | X29: - | Y29: 0 | Z29: 2251.48 | AA29: 0 | AI29: 45592 | AJ29: LLPR | AK29: 0.625 | AL29: 0 | AM29: 10.59
D30: 5560 | E30: Freight In/Out - (Noncapital related) | F30: 0 | G30: 434.94 | H30: 434.94 | I30: 0 | J30: -434.94 | N30: 45849 | O30: LLPE | P30: 20250630200000 | Q30: MF | R30: Link Not Available | S30: 45849 | T30: - | U30: - | V30: PAYROLL ENCUMBRANCES | W30: - | X30: - | Y30: 0 | Z30: 0 | AA30: -96 | AI30: 45606 | AJ30: LLPR | AK30: 0.625 | AL30: 0 | AM30: 10.73
D31: 5610 | E31: Subscriptions | F31: 0 | G31: 16.47 | H31: 16.47 | I31: 0 | J31: -16.47 | L31: 1212 Total | Y31: 0 | Z31: 23479.72 | AA31: 0 | AI31: 45620 | AJ31: LLPR | AK31: 0.625 | AL31: 0 | AM31: 3.34
D32: 5760 | E32: Noncapitalized Equipment - EDP | F32: 0 | G32: 7314.26 | H32: 7314.26 | I32: 0 | J32: -7314.26 | L32: 1213 | M32: Supp Comp Grad (ere 8) | N32: 45791 | O32: LLPE | P32: 20250514200001 | Q32: UE | R32: Link Not Available | S32: 45791 | T32: - | U32: - | V32: PAYROLL ENCUMBRANCES | W32: - | X32: - | Y32: 0 | Z32: 0 | AA32: 102 | AI32: 45634 | AJ32: LLPR | AK32: 0.625 | AL32: 0 | AM32: 11.45
D33: 5770 | E33: Noncapitalized Equipment - Other | F33: 0 | G33: 483.2 | H33: 483.2 | I33: 0 | J33: -483.2 | N33: 45819 | O33: LLPE | P33: 20250611200001 | Q33: MF | R33: Link Not Available | S33: 45819 | T33: - | U33: - | V33: PAYROLL ENCUMBRANCES | W33: - | X33: - | Y33: 0 | Z33: 0 | AA33: -39 | AI33: 45648 | AJ33: LLPR | AK33: 0.625 | AL33: 0 | AM33: 19.72
D34: 5780 | E34: Miscellaneous - Other Operating | F34: 0 | G34: 142.54 | H34: 142.54 | I34: 0 | J34: -142.54 | O34: LLPR | P34: 20250613100001 | Q34: UE | R34: Link Not Available | S34: 45819 | T34: - | U34: 11 | V34: NORMAL PAYROLL ACTIVITY | W34: - | X34: - | Y34: 0 | Z34: 588.33 | AA34: 0 | AI34: 45662 | AJ34: LLPR | AK34: 0.625 | AL34: 0 | AM34: 9.7
D35: 5899 | E35: Net Expenses - FSO Only | F35: 0 | G35: 0 | H35: 0 | I35: 0 | J35: 0 | U35: 12 | V35: NORMAL PAYROLL ACTIVITY | W35: - | X35: - | Y35: 0 | Z35: 588.33 | AA35: 0 | AI35: 45676 | AJ35: LLPR | AK35: 0.625 | AL35: 0 | AM35: 3.82
C36: TRAVEL | D36: 6240 | E36: TRAVEL-OUT STATE | F36: 0 | G36: 2044.72 | H36: 2044.72 | I36: 0 | J36: -2044.72 | N36: 45833 | O36: LLPE | P36: 20250625200001 | Q36: MF | R36: Link Not Available | S36: 45833 | T36: - | U36: - | V36: PAYROLL ENCUMBRANCES | W36: - | X36: - | Y36: 0 | Z36: 0 | AA36: -39 | AI36: 45690 | AJ36: LLPR | AK36: 0.625 | AL36: 0 | AM36: 9.41
D37: 6241 | E37: TRAVEL-OUT OF STATE AIRLINES | F37: 0 | G37: 444.47 | H37: 444.47 | I37: 0 | J37: -444.47 | O37: LLPR | P37: 20250627100001 | Q37: UE | R37: Link Not Available | S37: 45833 | T37: - | U37: 12 | V37: NORMAL PAYROLL ACTIVITY | W37: - | X37: - | Y37: 0 | Z37: 1176.66 | AA37: 0 | AI37: 45704 | AJ37: LLPR | AK37: 0.625 | AL37: 0 | AM37: 16.17
D38: 6242 | E38: TRAVEL-OUT STATE HOTEL | F38: 0 | G38: 72 | H38: 72 | I38: 0 | J38: -72 | N38: 45847 | O38: LLPR | P38: 20250711100001 | Q38: UE | R38: Link Not Available | S38: 45847 | T38: - | U38: 12 | V38: NORMAL PAYROLL ACTIVITY | W38: - | X38: - | Y38: 0 | Z38: 745.22 | AA38: 0 | AI38: 45718 | AJ38: LLPR | AK38: 0.625 | AL38: 0 | AM38: 12.79
C39: CAPITAL | D39: 7690 | E39: Scientific Equipment | F39: 0 | G39: 13409.23 | H39: 13409.23 | I39: 0 | J39: -13409.23 | N39: 45849 | O39: LLPE | P39: 20250630200000 | Q39: MF | R39: Link Not Available | S39: 45849 | T39: - | U39: - | V39: PAYROLL ENCUMBRANCES | W39: - | X39: - | Y39: 0 | Z39: 0 | AA39: -24 | AI39: 45732 | AJ39: LLPR | AK39: 0.625 | AL39: 0 | AM39: 12.5
C40: EXPENSES Total | F40: 219462 | G40: 153596.44 | H40: 153596.44 | I40: 280.92 | J40: 65584.64 | L40: 1213 Total | Y40: 0 | Z40: 3098.54 | AA40: 0 | AI40: 45746 | AJ40: LLPR | AK40: 0.625 | AL40: 0 | AM40: 15.88
B41: Grand Total | F41: 219462 | G41: -65865.56 | H41: -65865.56 | I41: 280.92 | J41: 285046.64 | L41: 1340 | M41: Student Wages (ere1) | N41: 45525 | O41: LLPE | P41: 20240821200001 | Q41: UE | R41: Link Not Available | S41: 45525 | T41: - | U41: - | V41: PAYROLL ENCUMBRANCES | W41: - | X41: - | Y41: 0 | Z41: 0 | AA41: 16385 | AI41: 45760 | AJ41: LLPR | AK41: 0.625 | AL41: 0 | AM41: 11.47
N42: 45539 | O42: LLPE | P42: 20240904200001 | Q42: MF | R42: Link Not Available | S42: 45539 | T42: - | U42: - | V42: PAYROLL ENCUMBRANCES | W42: - | X42: - | Y42: 0 | Z42: 0 | AA42: -725 | AI42: 45774 | AJ42: LLPR | AK42: 0.625 | AL42: 0 | AM42: 6.76
...

Sheet 1101935 FY26
B2: INCOME AND EXPENSE REPORT | L2: TRANSACTION REPORT | AC2: PAYROLL REPORT
B4: Account Number | C4: Consolidation Object Name | D4: Object Code | E4: Object Code Name | F4: Current Budget | G4: Fiscal Year Actuals | H4: Inception to Date | I4: Open Encumbrances | J4: Balance Available | L4: Object Code | M4: Object Code Name | N4: Transaction Date | O4: Document | P4: Document Number | Q4: Origin | R4: e-Doc Link | S4: Post Date | T4: Reference Document Number | U4: Organization Document Number | V4: Entry | W4: Document Description | X4: Vendor Name | Y4: Current Budget Amount | Z4: Current Month Actuals | AA4: Encumbrance Amount | AC4: Account Number | AD4: Sub Account Number | AE4: Employee Name | AF4: Position Number | AG4: Object Code | AH4: Object Code Name | AI4: Pay Period Earn Date | AJ4: Document Type Code | AK4: Job FTE | AL4: Hours Worked | AM4: Expenditure Amount
B5: 1101935 | C5: PERSONAL SERVICES | D5: 1190 | E5: Graduate Asst/Assoc Salaries (ere 8) | F5: 0 | G5: 2116.87 | H5: 2116.87 | I5: 14133 | J5: -16249.87 | L5: 1190 | M5: Graduate Asst/Assoc Salaries (ere 8) | N5: 45845 | O5: LLPE | P5: 20250706200001 | Q5: UE | R5: Link Not Available | S5: 45845 | T5: - | U5: - | V5: PAYROLL ENCUMBRANCES | W5: - | X5: - | Y5: 0 | Z5: 0 | AA5: 16250 | AC5: 1101935 | AD5: - | AE5: Hancock,Cason Montgomery | AF5: 2078743 | AG5: 1190 | AH5: Graduate Asst/Assoc Salaries (ere 8) | AI5: 45844 | AJ5: LLPR | AK5: 0.5 | AL5: 8 | AM5: 249.04
D6: 1212 | E6: Supp Com Regular App/Fac (ere 4) | F6: 0 | G6: 10614.12 | H6: 10614.12 | I6: 0 | J6: -10614.12 | N6: 45854 | O6: LLPE | P6: 20250716200001 | Q6: MF | R6: Link Not Available | S6: 45854 | T6: - | U6: - | V6: PAYROLL ENCUMBRANCES | W6: - | X6: - | Y6: 0 | Z6: 0 | AA6: -249 | AI6: 45858 | AJ6: LLPR | AK6: 0.5 | AL6: 20 | AM6: 622.61
D7: 1213 | E7: Supp Comp Grad (ere 8) | F7: 0 | G7: 3961.42 | H7: 3961.42 | I7: 0 | J7: -3961.42 | O7: LLPR | P7: 20250711100002 | Q7: UE | R7: Link Not Available | S7: 45854 | T7: - | U7: 01 | V7: NORMAL PAYROLL ACTIVITY | W7: - | X7: - | Y7: 0 | Z7: 249.04 | AA7: 0 | AI7: 45872 | AJ7: LLPR | AK7: 0.5 | AL7: 20 | AM7: 622.61
D8: 2119 | E8: Graduate Assistants ERE | F8: 0 | G8: 790.18 | H8: 790.18 | I8: 1837.29 | J8: -2627.47 | N8: 45861 | O8: LLPE | P8: 20250723200001 | Q8: MF | R8: Link Not Available | S8: 45861 | T8: - | U8: - | V8: PAYROLL ENCUMBRANCES | W8: - | X8: - | Y8: 0 | Z8: 0 | AA8: -623 | AI8: 45886 | AJ8: LLPR | AK8: 0.5 | AL8: 20 | AM8: 622.61
D9: 2121 | E9: Employee Full-Benefit ERE | F9: 0 | G9: 3396.5 | H9: 3396.5 | I9: 0 | J9: -3396.5 | O9: LLPR | P9: 20250725100001 | Q9: UE | R9: Link Not Available | S9: 45861 | T9: - | U9: 01 | V9: NORMAL PAYROLL ACTIVITY | W9: - | X9: - | Y9: 0 | Z9: 622.61 | AA9: 0 | AG9: 1190 Total | AL9: 68 | AM9: 2116.87
C10: GENERAL EXPENSES | D10: 3870 | E10: Express Shipping | F10: 0 | G10: 868.34 | H10: 868.34 | I10: 0 | J10: -868.34 | N10: 45875 | O10: LLPE | P10: 20250806200001 | Q10: MF | R10: Link Not Available | S10: 45875 | T10: - | U10: - | V10: PAYROLL ENCUMBRANCES | W10: - | X10: - | Y10: 0 | Z10: 0 | AA10: -622 | AG10: 2119 | AH10: Graduate Assistants ERE | AI10: 45844 | AJ10: LLPR | AK10: 0.5 | AL10: 0 | AM10: 32.38
D11: 4620 | E11: Software Licenses/Royalties | F11: 0 | G11: 179.4 | H11: 179.4 | I11: 0 | J11: -179.4 | O11: LLPR | P11: 20250808100001 | Q11: UE | R11: Link Not Available | S11: 45875 | T11: - | U11: 01 | V11: NORMAL PAYROLL ACTIVITY | W11: - | X11: - | Y11: 0 | Z11: 560.35 | AA11: 0 | AI11: 45858 | AJ11: LLPR | AK11: 0.5 | AL11: 0 | AM11: 80.94
D12: 5290 | E12: Research Supplies/Medical - Laboratory | F12: 0 | G12: 1551.28 | H12: 1551.28 | I12: 258.66 | J12: -1809.94 | U12: 02 | V12: NORMAL PAYROLL ACTIVITY | W12: - | X12: - | Y12: 0 | Z12: 62.26 | AA12: 0 | AI12: 45872 | AJ12: LLPR | AK12: 0.5 | AL12: 0 | AM12: 80.94
C13: TRAVEL | D13: 6240 | E13: TRAVEL-OUT STATE | F13: 0 | G13: 799.98 | H13: 799.98 | I13: 0 | J13: -799.98 | N13: 45889 | O13: LLPE | P13: 20250820200001 | Q13: MF | R13: Link Not Available | S13: 45889 | T13: - | U13: - | V13: PAYROLL ENCUMBRANCES | W13: - | X13: - | Y13: 0 | Z13: 0 | AA13: -623 | AI13: 45886 | AJ13: LLPR | AK13: 0.5 | AL13: 0 | AM13: 80.94
C14: EXPENSES Total | F14: 0 | G14: 24278.09 | H14: 24278.09 | I14: 16228.95 | J14: -40507.04 | O14: LLPR | P14: 20250822100001 | Q14: UE | R14: Link Not Available | S14: 45889 | T14: - | U14: 02 | V14: NORMAL PAYROLL ACTIVITY | W14: - | X14: - | Y14: 0 | Z14: 622.61 | AA14: 0 | AG14: 2119 Total | AL14: 0 | AM14: 275.2
B15: Grand Total | F15: 0 | G15: 24278.09 | H15: 24278.09 | I15: 16228.95 | J15: -40507.04 | L15: 1190 Total | Y15: 0 | Z15: 2116.87 | AA15: 14133 | AG15: 2120 | AH15: Graduate Assistants Tuition Remission ER | AI15: 45844 | AJ15: LLPR | AK15: 0.5 | AL15: 0 | AM15: 0
L16: 1212 | M16: Supp Com Regular App/Fac (ere 4) | N16: 45845 | O16: LLPE | P16: 20250706200001 | Q16: UE | R16: Link Not Available | S16: 45845 | T16: - | U16: - | V16: PAYROLL ENCUMBRANCES | W16: - | X16: - | Y16: 0 | Z16: 0 | AA16: 547 | AI16: 45858 | AJ16: LLPR | AK16: 0.5 | AL16: 0 | AM16: 0
N17: 45854 | O17: LLPE | P17: 20250716200001 | Q17: MF | R17: Link Not Available | S17: 45854 | T17: - | U17: - | V17: PAYROLL ENCUMBRANCES | W17: - | X17: - | Y17: 0 | Z17: 0 | AA17: -65 | AI17: 45872 | AJ17: LLPR | AK17: 0.5 | AL17: 0 | AM17: 0
O18: LLPR | P18: 20250711100002 | Q18: UE | R18: Link Not Available | S18: 45854 | T18: - | U18: 01 | V18: NORMAL PAYROLL ACTIVITY | W18: - | X18: - | Y18: 0 | Z18: 1929.84 | AA18: 0 | AI18: 45886 | AJ18: LLPR | AK18: 0.5 | AL18: 0 | AM18: 0
N19: 45861 | O19: LLPE | P19: 20250723200001 | Q19: MF | R19: Link Not Available | S19: 45861 | T19: - | U19: - | V19: PAYROLL ENCUMBRANCES | W19: - | X19: - | Y19: 0 | Z19: 0 | AA19: -160 | AG19: 2120 Total | AL19: 0 | AM19: 0
O20: LLPR | P20: 20250725100001 | Q20: UE | R20: Link Not Available | S20: 45861 | T20: - | U20: 01 | V20: NORMAL PAYROLL ACTIVITY | W20: - | X20: - | Y20: 0 | Z20: 3216.4 | AA20: 0 | AE20: McGhee,Alexander | AF20: 1867411 | AG20: 1212 | AH20: Supp Com Regular App/Fac (ere 4) | AI20: 45844 | AJ20: LLPR | AK20: 0.025 | AL20: 24 | AM20: 1929.84
N21: 45875 | O21: LLPE | P21: 20250806200001 | Q21: MF | R21: Link Not Available | S21: 45875 | T21: - | U21: - | V21: PAYROLL ENCUMBRANCES | W21: - | X21: - | Y21: 0 | Z21: 0 | AA21: -161 | AI21: 45858 | AJ21: LLPR | AK21: 0.025 | AL21: 40 | AM21: 3216.4
O22: LLPR | P22: 20250808100001 | Q22: UE | R22: Link Not Available | S22: 45875 | T22: - | U22: 01 | V22: NORMAL PAYROLL ACTIVITY | W22: - | X22: - | Y22: 0 | Z22: 2894.76 | AA22: 0 | AI22: 45872 | AJ22: LLPR | AK22: 0.025 | AL22: 40 | AM22: 3216.4
U23: 02 | V23: NORMAL PAYROLL ACTIVITY | W23: - | X23: - | Y23: 0 | Z23: 321.64 | AA23: 0 | AI23: 45886 | AJ23: LLPR | AK23: 0.025 | AL23: 28 | AM23: 2251.48
N24: 45889 | O24: LLPE | P24: 20250820200000 | Q24: MF | R24: Link Not Available | S24: 45889 | T24: - | U24: - | V24: PAYROLL ENCUMBRANCES | W24: - | X24: - | Y24: 0 | Z24: 0 | AA24: -161 | AG24: 1212 Total | AL24: 132 | AM24: 10614.12
O25: LLPR | P25: 20250822100001 | Q25: UE | R25: Link Not Available | S25: 45889 | T25: - | U25: 02 | V25: NORMAL PAYROLL ACTIVITY | W25: - | X25: - | Y25: 0 | Z25: 2251.48 | AA25: 0 | AG25: 2121 | AH25: Employee Full-Benefit ERE | AI25: 45844 | AJ25: LLPR | AK25: 0.025 | AL25: 0 | AM25: 617.55
L26: 1212 Total | Y26: 0 | Z26: 10614.12 | AA26: 0 | AI26: 45858 | AJ26: LLPR | AK26: 0.025 | AL26: 0 | AM26: 1029.24
L27: 1213 | M27: Supp Comp Grad (ere 8) | N27: 45845 | O27: LLPE | P27: 20250706200001 | Q27: UE | R27: Link Not Available | S27: 45845 | T27: - | U27: - | V27: PAYROLL ENCUMBRANCES | W27: - | X27: - | Y27: 0 | Z27: 0 | AA27: 133 | AI27: 45872 | AJ27: LLPR | AK27: 0.025 | AL27: 0 | AM27: 1029.24
N28: 45854 | O28: LLPE | P28: 20250716200001 | Q28: MF | R28: Link Not Available | S28: 45854 | T28: - | U28: - | V28: PAYROLL ENCUMBRANCES | W28: - | X28: - | Y28: 0 | Z28: 0 | AA28: -15 | AI28: 45886 | AJ28: LLPR | AK28: 0.025 | AL28: 0 | AM28: 720.47
O29: LLPR | P29: 20250711100002 | Q29: UE | R29: Link Not Available | S29: 45854 | T29: - | U29: 01 | V29: NORMAL PAYROLL ACTIVITY | W29: - | X29: - | Y29: 0 | Z29: 431.44 | AA29: 0 | AG29: 2121 Total | AL29: 0 | AM29: 3396.5
N30: 45861 | O30: LLPE | P30: 20250723200001 | Q30: MF | R30: Link Not Available | S30: 45861 | T30: - | U30: - | V30: PAYROLL ENCUMBRANCES | W30: - | X30: - | Y30: 0 | Z30: 0 | AA30: -40 | AE30: Starman,Alia Rose | AF30: 2059830 | AG30: 1213 | AH30: Supp Comp Grad (ere 8) | AI30: 45844 | AJ30: LLPR | AK30: 0.025 | AL30: 14.74 | AM30: 431.44
O31: LLPR | P31: 20250725100001 | Q31: UE | R31: Link Not Available | S31: 45861 | T31: - | U31: 01 | V31: NORMAL PAYROLL ACTIVITY | W31: - | X31: - | Y31: 0 | Z31: 1176.66 | AA31: 0 | AI31: 45858 | AJ31: LLPR | AK31: 0.025 | AL31: 40.2 | AM31: 1176.66
N32: 45875 | O32: LLPE | P32: 20250806200001 | Q32: MF | R32: Link Not Available | S32: 45875 | T32: - | U32: - | V32: PAYROLL ENCUMBRANCES | W32: - | X32: - | Y32: 0 | Z32: 0 | AA32: -39 | AI32: 45872 | AJ32: LLPR | AK32: 0.025 | AL32: 40.2 | AM32: 1176.66
O33: LLPR | P33: 20250808100001 | Q33: UE | R33: Link Not Available | S33: 45875 | T33: - | U33: 01 | V33: NORMAL PAYROLL ACTIVITY | W33: - | X33: - | Y33: 0 | Z33: 1058.99 | AA33: 0 | AI33: 45886 | AJ33: LLPR | AK33: 0.025 | AL33: 40.2 | AM33: 1176.66
U34: 02 | V34: NORMAL PAYROLL ACTIVITY | W34: - | X34: - | Y34: 0 | Z34: 117.67 | AA34: 0 | AG34: 1213 Total | AL34: 135.34 | AM34: 3961.42
N35: 45889 | O35: LLPE | P35: 20250820200000 | Q35: MF | R35: Link Not Available | S35: 45889 | T35: - | U35: - | V35: PAYROLL ENCUMBRANCES | W35: - | X35: - | Y35: 0 | Z35: 0 | AA35: -39 | AG35: 2119 | AH35: Graduate Assistants ERE | AI35: 45844 | AJ35: LLPR | AK35: 0.025 | AL35: 0 | AM35: 56.09
O36: LLPR | P36: 20250822100001 | Q36: UE | R36: Link Not Available | S36: 45889 | T36: - | U36: 02 | V36: NORMAL PAYROLL ACTIVITY | W36: - | X36: - | Y36: 0 | Z36: 1176.66 | AA36: 0 | AI36: 45858 | AJ36: LLPR | AK36: 0.025 | AL36: 0 | AM36: 152.96
L37: 1213 Total | Y37: 0 | Z37: 3961.42 | AA37: 0 | AI37: 45872 | AJ37: LLPR | AK37: 0.025 | AL37: 0 | AM37: 152.97
L38: 2119 | M38: Graduate Assistants ERE | N38: 45845 | O38: LLPE | P38: 20250706200001 | Q38: UE | R38: Link Not Available | S38: 45845 | T38: - | U38: - | V38: PAYROLL ENCUMBRANCES | W38: - | X38: - | Y38: 0 | Z38: 0 | AA38: 2129.79 | AI38: 45886 | AJ38: LLPR | AK38: 0.025 | AL38: 0 | AM38: 152.96
N39: 45854 | O39: LLPE | P39: 20250716200001 | Q39: MF | R39: Link Not Available | S39: 45854 | T39: - | U39: - | V39: PAYROLL ENCUMBRANCES | W39: - | X39: - | Y39: 0 | Z39: 0 | AA39: -34.32 | AG39: 2119 Total | AL39: 0 | AM39: 514.98
O40: LLPR | P40: 20250711100002 | Q40: UE | R40: Link Not Available | S40: 45854 | T40: - | U40: 01 | V40: NORMAL PAYROLL ACTIVITY | W40: - | X40: - | Y40: 0 | Z40: 88.47 | AA40: 0 | AG40: 2120 | AH40: Graduate Assistants Tuition Remission ER | AI40: 45844 | AJ40: LLPR | AK40: 0.025 | AL40: 0 | AM40: 0
N41: 45861 | O41: LLPE | P41: 20250723200001 | Q41: MF | R41: Link Not Available | S41: 45861 | T41: - | U41: - | V41: PAYROLL ENCUMBRANCES | W41: - | X41: - | Y41: 0 | Z41: 0 | AA41: -86.19 | AI41: 45858 | AJ41: LLPR | AK41: 0.025 | AL41: 0 | AM41: 0
O42: LLPR | P42: 20250725100001 | Q42: UE | R42: Link Not Available | S42: 45861 | T42: - | U42: 01 | V42: NORMAL PAYROLL ACTIVITY | W42: - | X42: - | Y42: 0 | Z42: 233.9 | AA42: 0 | AI42: 45872 | AJ42: LLPR | AK42: 0.025 | AL42: 0 | AM42: 0
...

Sheet 5406011 FY24
B2: INCOME AND EXPENSE REPORT | L2: TRANSACTION REPORT
B4: Account Number | C4: Consolidation Object Name | D4: Object Code | E4: Object Code Name | F4: Current Budget | G4: Fiscal Year Actuals | H4: Inception to Date | I4: Open Encumbrances | J4: Balance Available | L4: Object Code | M4: Object Code Name | N4: Transaction Date | O4: Document | P4: Document Number | Q4: Origin | R4: e-Doc Link | S4: Post Date | T4: Reference Document Number | U4: Organization Document Number | V4: Entry | W4: Document Description | X4: Vendor Name | Y4: Current Budget Amount | Z4: Current Month Actuals | AA4: Encumbrance Amount
B5: 5406011 | C5: OTHER REVENUE | D5: 0360 | E5: Gifts - U of A Foundation | F5: 0 | G5: -20000 | H5: -20000 | I5: 0 | J5: 20000 | L5: 0360 | M5: Gifts - U of A Foundation | N5: 45447 | O5: DI | P5: 28029356 | Q5: 01 | R5: View Document | S5: 45447 | T5: - | U5: TR060324 | V5: 20103408 | W5: Distribution Of Income And Expense - Electronic Payment Claim | X5: - | Y5: 0 | Z5: -20000 | AA5: 0
D6: 0899 | E6: Net Revenues - FSO Only | F6: 0 | G6: 0 | H6: 0 | I6: 0 | J6: 0 | L6: 0360 Total | Y6: 0 | Z6: -20000 | AA6: 0
C7: INCOME Total | F7: 0 | G7: -20000 | H7: -20000 | I7: 0 | J7: 20000 | L7: 7690 | M7: Scientific Equipment | N7: 45380 | O7: PO | P7: 27375160 | Q7: 01 | R7: View Document | S7: 45380 | T7: 749517 | U7: - | V7: NIKON INSTRUMENTS INC | W7: Purchase Order - Alexander McGhee - Nikon | X7: NIKON INSTRUMENTS INC | Y7: 0 | Z7: 0 | AA7: 20000
C8: GENERAL EXPENSES | D8: 5899 | E8: Net Expenses - FSO Only | F8: 0 | G8: 0 | H8: 0 | I8: 0 | J8: 0 | N8: 45449 | O8: PRNC | P8: 28062536 | Q8: 01 | R8: View Document | S8: 45449 | T8: 749517 | U8: - | V8: NIKON INSTRUMENTS INC | W8: PO: 749517 Vendor: NIKON INSTRUMENTS INC Account: UA 1101935 Amount: 540233.87 Pay Date: 06/19/2024 | X8: NIKON INSTRUMENTS INC | Y8: 0 | Z8: 20000.18 | AA8: -20000
C9: CAPITAL | D9: 7690 | E9: Scientific Equipment | F9: 0 | G9: 20000.18 | H9: 20000.18 | I9: 0 | J9: -20000.18 | L9: 7690 Total | Y9: 0 | Z9: 20000.18 | AA9: 0
C10: EXPENSES Total | F10: 0 | G10: 20000.18 | H10: 20000.18 | I10: 0 | J10: -20000.18
B11: Grand Total | F11: 0 | G11: 0.18 | H11: 0.18 | I11: 0 | J11: -0.18

Sheet 2176351 FY25
B2: INCOME AND EXPENSE REPORT | L2: TRANSACTION REPORT
B4: Account Number | C4: Consolidation Object Name | D4: Object Code | E4: Object Code Name | F4: Current Budget | G4: Fiscal Year Actuals | H4: Inception to Date | I4: Open Encumbrances | J4: Balance Available | L4: Object Code | M4: Object Code Name | N4: Transaction Date | O4: Document | P4: Document Number | Q4: Origin | R4: e-Doc Link | S4: Post Date | T4: Reference Document Number | U4: Organization Document Number | V4: Entry | W4: Document Description | X4: Vendor Name | Y4: Current Budget Amount | Z4: Current Month Actuals | AA4: Encumbrance Amount
B5: 2176351 | C5: GENERAL EXPENSES | D5: 4210 | E5: Miscellaneous Research Services | F5: 0 | G5: 1938.36 | H5: 1938.36 | I5: 0 | J5: -1938.36 | L5: 4210 | M5: Miscellaneous Research Services | N5: 45524 | O5: IB | P5: 20240820IL0 | Q5: AR | R5: Link Not Available | S5: 45524 | T5: - | U5: C-4621745 | V5: Alexander McGhee for PI Alexander McGhee | W5: - | X5: - | Y5: 0 | Z5: 20.58 | AA5: 0
D6: 4690 | E6: Rentals - Other | F6: 0 | G6: 423.18 | H6: 423.18 | I6: 0 | J6: -423.18 | N6: 45532 | O6: IB | P6: 20240828IL0 | Q6: CC | R6: Link Not Available | S6: 45532 | T6: - | U6: M-4640808 | V6: Alexander McGhee for PI Alexander McGhee | W6: - | X6: - | Y6: 0 | Z6: 45.5 | AA6: 0
D7: 5290 | E7: Research Supplies/Medical - Laboratory | F7: 0 | G7: 923.33 | H7: 923.33 | I7: 0 | J7: -923.33 | N7: 45561 | O7: IB | P7: 20240926IL0 | Q7: CC | R7: Link Not Available | S7: 45561 | T7: - | U7: E-4699543 | V7: Alia Rose Starman for PI Alexander McGhe | W7: - | X7: - | Y7: 0 | Z7: 521.08 | AA7: 0
D8: 5899 | E8: Net Expenses - FSO Only | F8: 0 | G8: 0 | H8: 0 | I8: 0 | J8: 0 | N8: 45587 | O8: IB | P8: 20241022IL0 | Q8: AR | R8: Link Not Available | S8: 45587 | T8: - | U8: C-4741506 | V8: Alexander McGhee for PI Alexander McGhee | W8: - | X8: - | Y8: 0 | Z8: 13.72 | AA8: 0
C9: EXPENSES Total | F9: 0 | G9: 3284.87 | H9: 3284.87 | I9: 0 | J9: -3284.87 | N9: 45595 | O9: IB | P9: 20241030IL0 | Q9: CC | R9: Link Not Available | S9: 45597 | T9: - | U9: E-4763206 | V9: Alia Rose Starman for PI Alexander McGhe | W9: - | X9: - | Y9: 0 | Z9: 26.03 | AA9: 0
B10: Grand Total | F10: 0 | G10: 3284.87 | H10: 3284.87 | I10: 0 | J10: -3284.87 | N10: 45622 | O10: IB | P10: 20241126IL0 | Q10: CC | R10: Link Not Available | S10: 45622 | T10: - | U10: B-4820552 | V10: Alexander McGhee for PI Alexander McGhee | W10: - | X10: - | Y10: 0 | Z10: 187 | AA10: 0
U11: E-4821580 | V11: Alexander McGhee for PI Alexander McGhee | W11: - | X11: - | Y11: 0 | Z11: 56.43 | AA11: 0
N12: 45708 | O12: IB | P12: 20250220IL0 | Q12: AR | R12: Link Not Available | S12: 45708 | T12: - | U12: C-4971584 | V12: Alexander McGhee for PI Alexander McGhee | W12: - | X12: - | Y12: 0 | Z12: 6.86 | AA12: 0
N13: 45772 | O13: IB | P13: 20250425IL0 | Q13: AR | R13: Link Not Available | S13: 45772 | T13: - | U13: C-5096661 | V13: Alexander McGhee for PI Alexander McGhee | W13: - | X13: - | Y13: 0 | Z13: 6.86 | AA13: 0
N14: 45775 | O14: IB | P14: 20250428IL0 | Q14: CC | R14: Link Not Available | S14: 45775 | T14: - | U14: E-5111826 | V14: Alia Rose Starman for PI Alexander McGhe | W14: - | X14: - | Y14: 0 | Z14: 43.3 | AA14: 0
N15: 45806 | O15: IB | P15: 20250529IL0 | Q15: CC | R15: Link Not Available | S15: 45806 | T15: - | U15: E-5177166 | V15: Alia Rose Starman for PI Alexander McGhe | W15: - | X15: - | Y15: 0 | Z15: 55.9 | AA15: 0
N16: 45826 | O16: IB | P16: 20250618IL0 | Q16: AR | R16: Link Not Available | S16: 45826 | T16: - | U16: C-5220325 | V16: Alexander McGhee for PI Alexander McGhee | W16: - | X16: - | Y16: 0 | Z16: 6.86 | AA16: 0
N17: 45838 | O17: IB | P17: 20250630IL0 | Q17: CC | R17: Link Not Available | S17: 45838 | T17: - | U17: E-5237977 | V17: Alia Rose Starman for PI Alexander McGhe | W17: - | X17: - | Y17: 0 | Z17: 28.26 | AA17: 0
U18: E-5260022 | V18: Alia Rose Starman for PI Alexander McGhe | W18: - | X18: - | Y18: 0 | Z18: 913.12 | AA18: 0
N19: 45841 | O19: IB | P19: 20250703IL0 | Q19: AR | R19: Link Not Available | S19: 45841 | T19: - | U19: C-5269553 | V19: Alexander McGhee for PI Alexander McGhee | W19: - | X19: - | Y19: 0 | Z19: 6.86 | AA19: 0
L20: 4210 Total | Y20: 0 | Z20: 1938.36 | AA20: 0
L21: 4690 | M21: Rentals - Other | N21: 45524 | O21: IB | P21: 20240820IL0 | Q21: AR | R21: Link Not Available | S21: 45524 | T21: - | U21: C-4621745 | V21: Alexander McGhee for PI Alexander McGhee | W21: - | X21: - | Y21: 0 | Z21: 8.64 | AA21: 0
N22: 45560 | O22: IB | P22: 20240925IL0 | Q22: AR | R22: Link Not Available | S22: 45560 | T22: - | U22: C-4688604 | V22: Alexander McGhee for PI Alexander McGhee | W22: - | X22: - | Y22: 0 | Z22: 33.48 | AA22: 0
N23: 45587 | O23: IB | P23: 20241022IL0 | Q23: AR | R23: Link Not Available | S23: 45587 | T23: - | U23: C-4741506 | V23: Alexander McGhee for PI Alexander McGhee | W23: - | X23: - | Y23: 0 | Z23: 37.08 | AA23: 0
N24: 45614 | O24: IB | P24: 20241118IL0 | Q24: AR | R24: Link Not Available | S24: 45614 | T24: - | U24: C-4800990 | V24: Alexander McGhee for PI Alexander McGhee | W24: - | X24: - | Y24: 0 | Z24: 39.06 | AA24: 0
N25: 45659 | O25: IB | P25: 20250102IL0 | Q25: AR | R25: Link Not Available | S25: 45659 | T25: - | U25: C-4857749 | V25: Alexander McGhee for PI Alexander McGhee | W25: - | X25: - | Y25: 0 | Z25: 37.8 | AA25: 0
N26: 45680 | O26: IB | P26: 20250123IL0 | Q26: AR | R26: Link Not Available | S26: 45680 | T26: - | U26: C-4911040 | V26: Alexander McGhee for PI Alexander McGhee | W26: - | X26: - | Y26: 0 | Z26: 39.06 | AA26: 0
N27: 45708 | O27: IB | P27: 20250220IL0 | Q27: AR | R27: Link Not Available | S27: 45708 | T27: - | U27: C-4971584 | V27: Alexander McGhee for PI Alexander McGhee | W27: - | X27: - | Y27: 0 | Z27: 39.06 | AA27: 0
N28: 45743 | O28: IB | P28: 20250327IL0 | Q28: AR | R28: Link Not Available | S28: 45743 | T28: - | U28: C-5032274 | V28: Alexander McGhee for PI Alexander McGhee | W28: - | X28: - | Y28: 0 | Z28: 35.28 | AA28: 0
N29: 45772 | O29: IB | P29: 20250425IL0 | Q29: AR | R29: Link Not Available | S29: 45772 | T29: - | U29: C-5096661 | V29: Alexander McGhee for PI Alexander McGhee | W29: - | X29: - | Y29: 0 | Z29: 39.06 | AA29: 0
N30: 45796 | O30: IB | P30: 20250519IL0 | Q30: AR | R30: Link Not Available | S30: 45796 | T30: - | U30: C-5152019 | V30: Alexander McGhee for PI Alexander McGhee | W30: - | X30: - | Y30: 0 | Z30: 37.8 | AA30: 0
N31: 45826 | O31: IB | P31: 20250618IL0 | Q31: AR | R31: Link Not Available | S31: 45826 | T31: - | U31: C-5220325 | V31: Alexander McGhee for PI Alexander McGhee | W31: - | X31: - | Y31: 0 | Z31: 39.06 | AA31: 0
N32: 45841 | O32: IB | P32: 20250703IL0 | Q32: AR | R32: Link Not Available | S32: 45841 | T32: - | U32: C-5269553 | V32: Alexander McGhee for PI Alexander McGhee | W32: - | X32: - | Y32: 0 | Z32: 37.8 | AA32: 0
L33: 4690 Total | Y33: 0 | Z33: 423.18 | AA33: 0
L34: 5290 | M34: Research Supplies/Medical - Laboratory | N34: 45524 | O34: IB | P34: 20240820IL0 | Q34: AR | R34: Link Not Available | S34: 45524 | T34: - | U34: C-4621745 | V34: Alexander McGhee for PI Alexander McGhee | W34: - | X34: - | Y34: 0 | Z34: 116.14 | AA34: 0
N35: 45587 | O35: IB | P35: 20241022IL0 | Q35: AR | R35: Link Not Available | S35: 45587 | T35: - | U35: C-4741506 | V35: Alexander McGhee for PI Alexander McGhee | W35: - | X35: - | Y35: 0 | Z35: 506.48 | AA35: 0
N36: 45708 | O36: IB | P36: 20250220IL0 | Q36: AR | R36: Link Not Available | S36: 45708 | T36: - | U36: C-4971584 | V36: Alexander McGhee for PI Alexander McGhee | W36: - | X36: - | Y36: 0 | Z36: 11.56 | AA36: 0
N37: 45772 | O37: IB | P37: 20250425IL0 | Q37: AR | R37: Link Not Available | S37: 45772 | T37: - | U37: C-5096661 | V37: Alexander McGhee for PI Alexander McGhee | W37: - | X37: - | Y37: 0 | Z37: 11.56 | AA37: 0
N38: 45826 | O38: IB | P38: 20250618IL0 | Q38: AR | R38: Link Not Available | S38: 45826 | T38: - | U38: C-5220325 | V38: Alexander McGhee for PI Alexander McGhee | W38: - | X38: - | Y38: 0 | Z38: 24.35 | AA38: 0
N39: 45841 | O39: IB | P39: 20250703IL0 | Q39: AR | R39: Link Not Available | S39: 45841 | T39: - | U39: C-5269553 | V39: Alexander McGhee for PI Alexander McGhee | W39: - | X39: - | Y39: 0 | Z39: 253.24 | AA39: 0
L40: 5290 Total | Y40: 0 | Z40: 923.33 | AA40: 0

Sheet 2176351 FY26
B2: INCOME AND EXPENSE REPORT | L2: TRANSACTION REPORT
B4: Account Number | C4: Consolidation Object Name | D4: Object Code | E4: Object Code Name | F4: Current Budget | G4: Fiscal Year Actuals | H4: Inception to Date | I4: Open Encumbrances | J4: Balance Available | L4: Object Code | M4: Object Code Name | N4: Transaction Date | O4: Document | P4: Document Number | Q4: Origin | R4: e-Doc Link | S4: Post Date | T4: Reference Document Number | U4: Organization Document Number | V4: Entry | W4: Document Description | X4: Vendor Name | Y4: Current Budget Amount | Z4: Current Month Actuals | AA4: Encumbrance Amount
B5: 2176351 | C5: GENERAL EXPENSES | D5: 4210 | E5: Miscellaneous Research Services | F5: 0 | G5: 13.72 | H5: 13.72 | I5: 0 | J5: -13.72 | L5: 4210 | M5: Miscellaneous Research Services | N5: 45888 | O5: IB | P5: 20250819IL0 | Q5: AR | R5: Link Not Available | S5: 45888 | T5: - | U5: C-5346987 | V5: Alexander McGhee for PI Alexander McGhee | W5: - | X5: - | Y5: 0 | Z5: 6.86 | AA5: 0
D6: 4690 | E6: Rentals - Other | F6: 0 | G6: 39.06 | H6: 39.06 | I6: 0 | J6: -39.06 | V6: Alia Rose Starman for PI Alexander McGhe | W6: - | X6: - | Y6: 0 | Z6: 6.86 | AA6: 0
D7: 5290 | E7: Research Supplies/Medical - Laboratory | F7: 0 | G7: 277.59 | H7: 277.59 | I7: 0 | J7: -277.59 | L7: 4210 Total | Y7: 0 | Z7: 13.72 | AA7: 0
C8: EXPENSES Total | F8: 0 | G8: 330.37 | H8: 330.37 | I8: 0 | J8: -330.37 | L8: 4690 | M8: Rentals - Other | N8: 45888 | O8: IB | P8: 20250819IL0 | Q8: AR | R8: Link Not Available | S8: 45888 | T8: - | U8: C-5346987 | V8: Alexander McGhee for PI Alexander McGhee | W8: - | X8: - | Y8: 0 | Z8: 39.06 | AA8: 0
B9: Grand Total | F9: 0 | G9: 330.37 | H9: 330.37 | I9: 0 | J9: -330.37 | L9: 4690 Total | Y9: 0 | Z9: 39.06 | AA9: 0
L10: 5290 | M10: Research Supplies/Medical - Laboratory | N10: 45888 | O10: IB | P10: 20250819IL0 | Q10: AR | R10: Link Not Available | S10: 45888 | T10: - | U10: C-5346987 | V10: Alexander McGhee for PI Alexander McGhee | W10: - | X10: - | Y10: 0 | Z10: 253.24 | AA10: 0
V11: Alia Rose Starman for PI Alexander McGhe | W11: - | X11: - | Y11: 0 | Z11: 24.35 | AA11: 0
L12: 5290 Total | Y12: 0 | Z12: 277.59 | AA12: 0

Sheet 2176300 BMEAM FY24
B2: INCOME AND EXPENSE REPORT | L2: TRANSACTION REPORT
B4: Account Number | C4: Consolidation Object Name | D4: Object Code | E4: Object Code Name | F4: Current Budget | G4: Fiscal Year Actuals | H4: Inception to Date | I4: Open Encumbrances | J4: Balance Available | L4: Object Code | M4: Object Code Name | N4: Transaction Date | O4: Document | P4: Document Number | Q4: Origin | R4: e-Doc Link | S4: Post Date | T4: Reference Document Number | U4: Organization Document Number | V4: Entry | W4: Document Description | X4: Vendor Name | Y4: Current Budget Amount | Z4: Current Month Actuals | AA4: Encumbrance Amount
B5: 2176300-BMEAM | C5: GENERAL EXPENSES | D5: 5490 | E5: Operating Supplies - Other | F5: 0 | G5: 181.09 | H5: 181.09 | I5: 0 | J5: -181.09 | L5: 5490 | M5: Operating Supplies - Other | N5: 45469 | O5: PCDO | P5: 28155297 | Q5: 01 | R5: View Document | S5: 45469 | T5: - | U5: - | V5: Wall mount for gas cylinders | W5: Procurement Card - 5745 / MCGHEE, ALEXANDER / 50424 / MCMASTER-CARR / $217.60 | X5: - | Y5: 0 | Z5: 181.09 | AA5: 0
D6: 5560 | E6: Freight In/Out - (Noncapital related) | F6: 0 | G6: 36.51 | H6: 36.51 | I6: 0 | J6: -36.51 | L6: 5490 Total | Y6: 0 | Z6: 181.09 | AA6: 0
D7: 5899 | E7: Net Expenses - FSO Only | F7: 0 | G7: 0 | H7: 0 | I7: 0 | J7: 0 | L7: 5560 | M7: Freight In/Out - (Noncapital related) | N7: 45469 | O7: PCDO | P7: 28155297 | Q7: 01 | R7: View Document | S7: 45469 | T7: - | U7: - | V7: shipping cost | W7: Procurement Card - 5745 / MCGHEE, ALEXANDER / 50424 / MCMASTER-CARR / $217.60 | X7: - | Y7: 0 | Z7: 36.51 | AA7: 0
C8: EXPENSES Total | F8: 0 | G8: 217.6 | H8: 217.6 | I8: 0 | J8: -217.6 | L8: 5560 Total | Y8: 0 | Z8: 36.51 | AA8: 0
B9: GRAND TOTAL | F9: 0 | G9: 217.6 | H9: 217.6 | I9: 0 | J9: -217.6

Sheet 2176300 BMEAM FY25
B2: INCOME AND EXPENSE REPORT | L2: TRANSACTION REPORT
B4: Account Number | C4: Consolidation Object Name | D4: Object Code | E4: Object Code Name | F4: Current Budget | G4: Fiscal Year Actuals | H4: Inception to Date | I4: Open Encumbrances | J4: Balance Available | L4: Object Code | M4: Object Code Name | N4: Transaction Date | O4: Document | P4: Document Number | Q4: Origin | R4: e-Doc Link | S4: Post Date | T4: Reference Document Number | U4: Organization Reference ID | V4: Entry | W4: Document Description | X4: Vendor Name | Y4: Current Budget Amount | Z4: Current Month Actuals | AA4: Encumbrance Amount
B5: 2176300-BMEAM | C5: GENERAL EXPENSES | D5: 3510 | E5: R/M Services-Buildings | F5: 0 | G5: 0 | H5: 0 | I5: 0 | J5: 0 | L5: 3510 | M5: R/M Services-Buildings | N5: 45772 | O5: GEC | P5: 30783481 | Q5: 01 | R5: View Document | S5: 45772 | T5: - | U5: 1664396 | V5: FM-20240926FM1: S5914/John Gaff/need ... | W5: General Error Correction - BME IDC - Main Account Clean Up | X5: - | Y5: 0 | Z5: 29.38 | AA5: 0
D6: 3870 | E6: Express Shipping | F6: 0 | G6: 0 | H6: 0 | I6: 0 | J6: 0 | V6: FM-20241016FM1: S5914/John Gaff/need ... | W6: General Error Correction - BME IDC - Main Account Clean Up | X6: - | Y6: 0 | Z6: 62.5 | AA6: 0
D7: 4620 | E7: Software Licenses/Royalties | F7: 0 | G7: 0 | H7: 0 | I7: 0 | J7: 0 | V7: FM-20241219FM1: S5914/John Gaff/need ... | W7: General Error Correction - BME IDC - Main Account Clean Up | X7: - | Y7: 0 | Z7: 250 | AA7: 0
D8: 5150 | E8: Data Processing Supplies | F8: 0 | G8: 0 | H8: 0 | I8: 0 | J8: 0 | N8: 45849 | O8: YEGE | P8: 31553281 | Q8: 01 | R8: View Document | S8: 45849 | T8: - | U8: 1664396 | V8: 01-30783481: FM-20240926FM1: S5914/Jo... | W8: Year End General Error Correction - Moving expenses to correct account | X8: - | Y8: 0 | Z8: -29.38 | AA8: 0
D9: 5230 | E9: Office Supplies | F9: 0 | G9: 0 | H9: 0 | I9: 0 | J9: 0 | V9: 01-30783481: FM-20241016FM1: S5914/Jo... | W9: Year End General Error Correction - Moving expenses to correct account | X9: - | Y9: 0 | Z9: -62.5 | AA9: 0
D10: 5290 | E10: Research Supplies/Medical - Laboratory | F10: 0 | G10: 0 | H10: 0 | I10: 0 | J10: 0 | V10: 01-30783481: FM-20241219FM1: S5914/Jo... | W10: Year End General Error Correction - Moving expenses to correct account | X10: - | Y10: 0 | Z10: -250 | AA10: 0
D11: 5490 | E11: Operating Supplies - Other | F11: 0 | G11: 0 | H11: 0 | I11: 0 | J11: 0 | L11: 3510 Total | Y11: 0 | Z11: 0 | AA11: 0
D12: 5520 | E12: Conference Registration Fees | F12: 0 | G12: 0 | H12: 0 | I12: 0 | J12: 0 | L12: 3870 | M12: Express Shipping | N12: 45531 | O12: PCDO | P12: 28659256 | Q12: 01 | R12: View Document | S12: 45531 | T12: - | U12: - | V12: Delivery | W12: Procurement Card - 5745 / MCGHEE, ALEXANDER / 76752 / UPS E8K138BGNLD / $95.32 | X12: - | Y12: 0 | Z12: 95.32 | AA12: 0
D13: 5535 | E13: Purchasing Transaction Fees | F13: 0 | G13: 0 | H13: 0 | I13: 0 | J13: 0 | N13: 45849 | O13: YEGE | P13: 31553281 | Q13: 01 | R13: View Document | S13: 45849 | T13: - | U13: - | V13: 01-28659256: Delivery | W13: Year End General Error Correction - Moving expenses to correct account | X13: - | Y13: 0 | Z13: -95.32 | AA13: 0
D14: 5560 | E14: Freight In/Out - (Noncapital related) | F14: 0 | G14: 0 | H14: 0 | I14: 0 | J14: 0 | L14: 3870 Total | Y14: 0 | Z14: 0 | AA14: 0
D15: 5760 | E15: Noncapitalized Equipment - EDP | F15: 0 | G15: 0 | H15: 0 | I15: 0 | J15: 0 | L15: 4620 | M15: Software Licenses/Royalties | N15: 45554 | O15: PCDO | P15: 28849510 | Q15: 01 | R15: View Document | S15: 45554 | T15: - | U15: - | V15: Aid for LaTex code | W15: Procurement Card - Auto Approve 09/19/2024 12:18 AM / 88921 / OVERLEAF SHARELATEX / $200.99 | X15: - | Y15: 0 | Z15: 199 | AA15: 0
D16: 5899 | E16: Net Expenses - FSO Only | F16: 0 | G16: 0 | H16: 0 | I16: 0 | J16: 0 | V16: Use Tax 5.600% on 199.00 | W16: Procurement Card - Auto Approve 09/19/2024 12:18 AM / 88921 / OVERLEAF SHARELATEX / $200.99 | X16: - | Y16: 0 | Z16: 11.14 | AA16: 0
C17: TRAVEL | D17: 6240 | E17: TRAVEL-OUT STATE | F17: 0 | G17: 322.72 | H17: 322.72 | I17: 0 | J17: -322.72 | N17: 45560 | O17: PCDO | P17: 28915583 | Q17: 01 | R17: View Document | S17: 45560 | T17: - | U17: - | V17: Coding development | W17: Procurement Card - 5745 / MCGHEE, ALEXANDER / 91406 / GITHUB, INC. / $100.00 | X17: - | Y17: 0 | Z17: 100 | AA17: 0
D18: 6241 | E18: TRAVEL-OUT OF STATE AIRLINES | F18: 0 | G18: 0 | H18: 0 | I18: 0 | J18: 0 | N18: 45849 | O18: YEGE | P18: 31553281 | Q18: 01 | R18: View Document | S18: 45849 | T18: - | U18: - | V18: 01-28849510: Aid for LaTex code | W18: Year End General Error Correction - Moving expenses to correct account | X18: - | Y18: 0 | Z18: -199 | AA18: 0
D19: 6242 | E19: TRAVEL-OUT STATE HOTEL | F19: 0 | G19: 495 | H19: 495 | I19: 0 | J19: -495 | V19: 01-28849510: Use Tax 5.600% on 199.00 | W19: Year End General Error Correction - Moving expenses to correct account | X19: - | Y19: 0 | Z19: -11.14 | AA19: 0
